<?xml version="1.0" ?>
<!-- =================================================================================== -->
<!-- |    This document was autogenerated by xacro from xacro/robot.xacro              | -->
<!-- |    EDITING THIS FILE BY HAND IS NOT RECOMMENDED                                 | -->
<!-- =================================================================================== -->
<robot name="sirius_diff_new">
  <material name="black">
    <color rgba="0.0 0.0 0.0 1.0"/>
  </material>
  <material name="blue">
    <color rgba="0.0 0.0 0.8 1.0"/>
  </material>
  <material name="green">
    <color rgba="0.0 0.8 0.0 1.0"/>
  </material>
  <material name="grey">
    <color rgba="0.2 0.2 0.2 1.0"/>
  </material>
  <material name="silver">
    <color rgba="0.9137254901960784 0.9137254901960784 0.8470588235294118 1.0"/>
  </material>
  <material name="orange">
    <color rgba="1.0 0.4235294117647059 0.0392156862745098 1.0"/>
  </material>
  <material name="brown">
    <color rgba="0.8705882352941177 0.8117647058823529 0.7647058823529411 1.0"/>
  </material>
  <material name="red">
    <color rgba="0.8 0.0 0.0 1.0"/>
  </material>
  <material name="white">
    <color rgba="1.0 1.0 1.0 1.0"/>
  </material>
  <!-- ros_control plugin -->
  <gazebo>
    <plugin filename="liblegged_hw_sim.so" name="gazebo_ros_control">
      <robotNamespace>/</robotNamespace>
      <robotParam>legged_robot_description</robotParam>
      <robotSimType>legged_gazebo/LeggedHWSim</robotSimType>
    </plugin>
  </gazebo>
  <!-- Show the trajectory of trunk center. -->
  <!--    <gazebo>-->
  <!--        <plugin name="3dplot" filename="libLinkPlot3DPlugin.so">-->
  <!--            <frequency>10</frequency>-->
  <!--            <plot>-->
  <!--                <link>base</link>-->
  <!--                <pose>0 0 0 0 0 0</pose>-->
  <!--                <material>Gazebo/Yellow</material>-->
  <!--            </plot>-->
  <!--        </plugin>-->
  <!--    </gazebo>-->
  <!--    <gazebo>-->
  <!--        <plugin name="3dplot" filename="libLinkPlot3DPlugin.so">-->
  <!--            <frequency>300</frequency>-->
  <!--            <plot>-->
  <!--                <link>FR_foot</link>-->
  <!--                <pose>0 0 0 0 0 0</pose>-->
  <!--                <material>Gazebo/Red</material>-->
  <!--            </plot>-->
  <!--        </plugin>-->
  <!--    </gazebo>-->
  <!--    <gazebo>-->
  <!--        <plugin name="3dplot" filename="libLinkPlot3DPlugin.so">-->
  <!--            <frequency>300</frequency>-->
  <!--            <plot>-->
  <!--                <link>FL_foot</link>-->
  <!--                <pose>0 0 0 0 0 0</pose>-->
  <!--                <material>Gazebo/Red</material>-->
  <!--            </plot>-->
  <!--        </plugin>-->
  <!--    </gazebo>-->
  <!--    <gazebo>-->
  <!--        <plugin name="3dplot" filename="libLinkPlot3DPlugin.so">-->
  <!--            <frequency>300</frequency>-->
  <!--            <plot>-->
  <!--                <link>RR_foot</link>-->
  <!--                <pose>0 0 0 0 0 0</pose>-->
  <!--                <material>Gazebo/Red</material>-->
  <!--            </plot>-->
  <!--        </plugin>-->
  <!--    </gazebo>-->
  <!--    <gazebo>-->
  <!--        <plugin name="3dplot" filename="libLinkPlot3DPlugin.so">-->
  <!--            <frequency>300</frequency>-->
  <!--            <plot>-->
  <!--                <link>RL_foot</link>-->
  <!--                <pose>0 0 0 0 0 0</pose>-->
  <!--                <material>Gazebo/Red</material>-->
  <!--            </plot>-->
  <!--        </plugin>-->
  <!--    </gazebo>-->
  <!--    <gazebo>-->
  <!--        <plugin filename="libgazebo_ros_force.so" name="gazebo_ros_force">-->
  <!--            <bodyName>trunk</bodyName>-->
  <!--            <topicName>/apply_force/trunk</topicName>-->
  <!--        </plugin>-->
  <!--    </gazebo>-->
  <gazebo reference="imu_link">
    <gravity>true</gravity>
    <sensor name="imu_sensor" type="imu">
      <always_on>true</always_on>
      <update_rate>1000</update_rate>
      <visualize>true</visualize>
      <topic>__default_topic__</topic>
      <plugin filename="libgazebo_ros_imu_sensor.so" name="imu_plugin">
        <topicName>trunk_imu</topicName>
        <bodyName>imu_link</bodyName>
        <updateRateHZ>1000.0</updateRateHZ>
        <gaussianNoise>0.0</gaussianNoise>
        <xyzOffset>0 0 0</xyzOffset>
        <rpyOffset>0 0 0</rpyOffset>
        <frameName>imu_link</frameName>
      </plugin>
      <pose>0 0 0 0 0 0</pose>
    </sensor>
  </gazebo>
  <!-- Foot contacts. -->
  <!--    <gazebo reference="FR_calf">-->
  <!--        <sensor name="FR_foot_contact" type="contact">-->
  <!--            <update_rate>100</update_rate>-->
  <!--            <plugin name="contactPlugin" filename="libunitreeFootContactPlugin.so"/>-->
  <!--            <contact>-->
  <!--                <collision>FR_calf_fixed_joint_lump__FR_foot_collision_1</collision>-->
  <!--            </contact>-->
  <!--        </sensor>-->
  <!--    </gazebo>-->
  <!--    <gazebo reference="FL_calf">-->
  <!--        <sensor name="FL_foot_contact" type="contact">-->
  <!--            <update_rate>100</update_rate>-->
  <!--            <plugin name="contactPlugin" filename="libunitreeFootContactPlugin.so"/>-->
  <!--            <contact>-->
  <!--                <collision>FL_calf_fixed_joint_lump__FL_foot_collision_1</collision>-->
  <!--            </contact>-->
  <!--        </sensor>-->
  <!--    </gazebo>-->
  <!--    <gazebo reference="RR_calf">-->
  <!--        <sensor name="RR_foot_contact" type="contact">-->
  <!--            <update_rate>100</update_rate>-->
  <!--            <plugin name="contactPlugin" filename="libunitreeFootContactPlugin.so"/>-->
  <!--            <contact>-->
  <!--                <collision>RR_calf_fixed_joint_lump__RR_foot_collision_1</collision>-->
  <!--            </contact>-->
  <!--        </sensor>-->
  <!--    </gazebo>-->
  <!--    <gazebo reference="RL_calf">-->
  <!--        <sensor name="RL_foot_contact" type="contact">-->
  <!--            <update_rate>100</update_rate>-->
  <!--            <plugin name="contactPlugin" filename="libunitreeFootContactPlugin.so"/>-->
  <!--            <contact>-->
  <!--                <collision>RL_calf_fixed_joint_lump__RL_foot_collision_1</collision>-->
  <!--            </contact>-->
  <!--        </sensor>-->
  <!--    </gazebo>-->
  <!--    &lt;!&ndash; Visualization of Foot contacts. &ndash;&gt;-->
  <!--    <gazebo reference="FR_foot">-->
  <!--        <visual>-->
  <!--            <plugin name="drawForcePlugin" filename="libunitreeDrawForcePlugin.so">-->
  <!--                <topicName>FR_foot_contact</topicName>-->
  <!--            </plugin>-->
  <!--        </visual>-->
  <!--    </gazebo>-->
  <!--    <gazebo reference="FL_foot">-->
  <!--        <visual>-->
  <!--            <plugin name="drawForcePlugin" filename="libunitreeDrawForcePlugin.so">-->
  <!--                <topicName>FL_foot_contact</topicName>-->
  <!--            </plugin>-->
  <!--        </visual>-->
  <!--    </gazebo>-->
  <!--    <gazebo reference="RR_foot">-->
  <!--        <visual>-->
  <!--            <plugin name="drawForcePlugin" filename="libunitreeDrawForcePlugin.so">-->
  <!--                <topicName>RR_foot_contact</topicName>-->
  <!--            </plugin>-->
  <!--        </visual>-->
  <!--    </gazebo>-->
  <!--    <gazebo reference="RL_foot">-->
  <!--        <visual>-->
  <!--            <plugin name="drawForcePlugin" filename="libunitreeDrawForcePlugin.so">-->
  <!--                <topicName>RL_foot_contact</topicName>-->
  <!--            </plugin>-->
  <!--        </visual>-->
  <!--    </gazebo>-->
  <gazebo reference="base">
    <material>Gazebo/Green</material>
    <turnGravityOff>false</turnGravityOff>
  </gazebo>
  <gazebo reference="trunk">
    <mu1>0.6</mu1>
    <mu2>0.6</mu2>
    <kp value="1000000.0"/>
    <kd value="10.0"/>
  </gazebo>
  <gazebo reference="stick_link">
    <mu1>0.2</mu1>
    <mu2>0.2</mu2>
    <material>Gazebo/White</material>
  </gazebo>
  <gazebo reference="imu_link">
    <mu1>0.2</mu1>
    <mu2>0.2</mu2>
    <material>Gazebo/Red</material>
  </gazebo>
  <gazebo reference="imu_joint">
    <disableFixedJointLumping>true</disableFixedJointLumping>
  </gazebo>
  <link name="base">
    <visual>
      <origin rpy="0 0 0" xyz="0 0 0"/>
      <geometry>
        <box size="0.001 0.001 0.001"/>
      </geometry>
    </visual>
  </link>
  <joint name="floating_base" type="fixed">
    <origin rpy="0 0 0" xyz="0 0 0"/>
    <parent link="base"/>
    <child link="trunk"/>
  </joint>
  <link name="trunk">
    <visual>
      <origin rpy="0 0 0" xyz="-0 0 0"/>
      <geometry>
        <mesh filename="../meshes/base_link.dae" scale="1 1 1"/>
      </geometry>
    </visual>
    <collision>
      <origin rpy="0 0 0" xyz="0 0 0"/>
      <geometry>
        <!--                <mesh filename="../meshes/base_link.dae" scale="1 1 1"/>-->
        <box size="0.525 0.25 0.114"/>
      </geometry>
    </collision>
    <collision>
      <origin rpy="0 0 0" xyz="0.418 0 0"/>
      <geometry>
        <box size="0.105 0.21 0.16"/>
      </geometry>
    </collision>
    <collision>
      <origin rpy="0 0 0" xyz="-0.4105 0 0"/>
      <geometry>
        <box size="0.09 0.21 0.16"/>
      </geometry>
    </collision>
    <collision>
      <origin rpy="0 0 0" xyz="0.3905 -0.06 -0.0718"/>
      <geometry>
        <sphere radius="0.02"/>
      </geometry>
    </collision>
    <collision>
      <origin rpy="0 0 0" xyz="-0.3905 -0.06 -0.0718"/>
      <geometry>
        <sphere radius="0.02"/>
      </geometry>
    </collision>
    <collision>
      <origin rpy="0 0 0" xyz="0.3905 0.06 -0.0718"/>
      <geometry>
        <sphere radius="0.02"/>
      </geometry>
    </collision>
    <collision>
      <origin rpy="0 0 0" xyz="-0.3905 0.06 -0.0718"/>
      <geometry>
        <sphere radius="0.02"/>
      </geometry>
    </collision>
    <inertial>
      <origin rpy="0 0 0" xyz="0.02677303 0.0 0.00632505"/>
      <mass value="21.5654"/>
      <inertia ixx="0.10767656" ixy="3.3e-07" ixz="-0.0087152" iyy="2.82545726" iyz="-2.4e-07" izz="2.85571634"/>
    </inertial>
  </link>
  <joint name="imu_joint" type="fixed">
    <parent link="trunk"/>
    <child link="imu_link"/>
    <origin rpy="0 0 0" xyz="-0.01592 -0.06659 -0.00617"/>
  </joint>
  <link name="imu_link">
    <inertial>
      <mass value="0.001"/>
      <origin rpy="0 0 0" xyz="0 0 0"/>
      <inertia ixx="0.0001" ixy="0" ixz="0" iyy="0.0001" iyz="0" izz="0.0001"/>
    </inertial>
    <visual>
      <origin rpy="0 0 0" xyz="0 0 0"/>
      <geometry>
        <box size="0.001 0.001 0.001"/>
      </geometry>
      <!-- <material name="red"/> -->
    </visual>
    <collision>
      <origin rpy="0 0 0" xyz="0 0 0"/>
      <geometry>
        <box size=".001 .001 .001"/>
      </geometry>
    </collision>
  </link>
  <!--       *********************************** abad description *************8-->
  <joint name="RF_HAA" type="revolute">
    <!--            insert start block from parent file-->
    <origin rpy="0 0 0" xyz="0.314 -0.05 0"/>
    <parent link="trunk"/>
    <child link="RF_hip"/>
    <axis xyz="1 0 0"/>
    <dynamics damping="0" friction="0.01"/>
    <limit effort="45" lower="-0.8028514559173915" upper="0.8028514559173915" velocity="21"/>
  </joint>
  <link name="RF_hip">
    <visual>
      <origin rpy="0 0 0" xyz="0 0 0"/>
      <geometry>
        <mesh filename="../meshes/fr_abad_link.dae" scale="1 1 1"/>
      </geometry>
      <material name="orange"/>
    </visual>
    <collision>
      <origin rpy="1.5707963267948966 0 0" xyz="0.0 -0.03 0"/>
      <geometry>
        <cylinder length="0.09" radius="0.055"/>
      </geometry>
    </collision>
    <!--            tochange here-->
    <!--            <collision>-->
    <!--                <origin rpy="${pi/2} 0 0"-->
    <!--                        xyz="${abad_origin_x*front_hind_mirror} ${abad_origin_y*left_right_mirror} 0"/>-->
    <!--                <geometry>-->
    <!--                    <xacro:if value="${(left_right_bool == True) and (front_hind_bool == True)}">-->
    <!--                        <mesh filename="../meshes/fl_abad_link.dae"-->
    <!--                              scale="1 1 1"/>-->
    <!--                    </xacro:if>-->
    <!--                    <xacro:if value="${(left_right_bool == False) and (front_hind_bool == True)}">-->
    <!--                        <mesh filename="../meshes/fr_abad_link.dae"-->
    <!--                              scale="1 1 1"/>-->
    <!--                    </xacro:if>-->
    <!--                    <xacro:if value="${(left_right_bool == True) and (front_hind_bool == False)}">-->
    <!--                        <mesh filename="../meshes/rl_abad_link.dae"-->
    <!--                              scale="1 1 1"/>-->
    <!--                    </xacro:if>-->
    <!--                    <xacro:if value="${(left_right_bool == False) and (front_hind_bool == False)}">-->
    <!--                        <mesh filename="../meshes/rr_abad_link.dae"-->
    <!--                              scale="1 1 1"/>-->
    <!--                    </xacro:if>-->
    <!--                </geometry>-->
    <!--            </collision>-->
    <inertial>
      <origin rpy="0 0 0" xyz="1.787e-05 -0.00607236 -8.968e-05"/>
      <mass value="0.7766"/>
      <inertia ixx="0.00066364" ixy="-0.0" ixz="0" iyy="0.00093712" iyz="-2.89e-06" izz="0.00106375"/>
    </inertial>
  </link>
  <!--        *************************************** hip description ******************************************************-->
  <joint name="RF_HFE" type="revolute">
    <origin rpy="0 0 0" xyz="0 -0.1408 0"/>
    <parent link="RF_hip"/>
    <child link="RF_thigh"/>
    <axis xyz="0 1 0"/>
    <dynamics damping="0" friction="0.01"/>
    <limit effort="45" lower="-4.1887902047863905" upper="4.1887902047863905" velocity="21"/>
  </joint>
  <link name="RF_thigh">
    <visual>
      <origin rpy="0 0 0" xyz="0 0 0"/>
      <geometry>
        <mesh filename="../meshes/fr_hip_link.dae" scale="1 1 1"/>
      </geometry>
      <material name="orange"/>
    </visual>
    <collision>
      <origin rpy="1.5707963267948966 0 0" xyz="0 0 0"/>
      <geometry>
        <cylinder length="0.039" radius="0.0375"/>
      </geometry>
    </collision>
    <collision>
      <origin rpy="1.5707963267948966 0 0" xyz="0 0.04 0"/>
      <geometry>
        <cylinder length="0.048" radius="0.05"/>
      </geometry>
    </collision>
    <collision>
      <origin rpy="0 1.5707963267948966 0" xyz="0 0 -0.1382"/>
      <geometry>
        <box size="0.2159 0.05 0.05"/>
      </geometry>
    </collision>
    <inertial>
      <origin rpy="0 0 0" xyz="-0.00142243 0.02451835 -0.06737031"/>
      <mass value="2.1028"/>
      <inertia ixx="0.03392455" ixy="1.021e-05" ixz="-0.00038283" iyy="0.03116088" iyz="4.69e-05" izz="0.00483256"/>
    </inertial>
  </link>
  <!--************************************************ knee description ***********************************************************8-->
  <joint name="RF_KFE" type="revolute">
    <origin rpy="0 0 0" xyz="0.0 -0.0 -0.272"/>
    <parent link="RF_thigh"/>
    <child link="RF_calf"/>
    <axis xyz="0 1 0"/>
    <dynamics damping="0" friction="0.01"/>
    <limit effort="80" lower="-2.6965336943312392" upper="-0.9162978572970231" velocity="21"/>
  </joint>
  <link name="RF_calf">
    <visual>
      <origin rpy="0 0 0" xyz="0 0 0"/>
      <geometry>
        <mesh filename="../meshes/fr_knee_link.STL" scale="1 1 1"/>
      </geometry>
      <material name="orange"/>
    </visual>
    <collision>
      <origin rpy="0 0 0" xyz="0 0 0.0"/>
      <geometry>
        <mesh filename="../meshes/fr_knee_link.STL" scale="1 1 1"/>
      </geometry>
    </collision>
    <inertial>
      <origin rpy="0 0 0" xyz="-0.00804831 1.07e-06 -0.12689414"/>
      <mass value="0.4842"/>
      <inertia ixx="0.01527064" ixy="0.0" ixz="-0.00063844" iyy="0.01543121" iyz="2e-08" izz="0.00022068"/>
    </inertial>
  </link>
  <!--       ******************************* foot description ********************************8-->
  <joint name="RF_foot_fixed" type="fixed" dont_collapse="true">
    <origin rpy="0 0 0" xyz="0 0 -0.303542171457651"/>
    <!-- <origin rpy="0 0 0" xyz="0 0 0"/> -->
    <parent link="RF_calf"/>
    <child link="RF_FOOT"/>
  </joint>
  <link name="RF_FOOT">
    <visual>
      <origin rpy="0 0 0" xyz="0 0 0"/>
      <geometry>
        <mesh filename="../meshes/fr_foot_link.STL" scale="1 1 1"/>
      </geometry>
    </visual>
    <collision>
      <origin rpy="0 0 0" xyz="0 0 0"/>
        <!-- <geometry>
          <sphere radius="0.03"/>
        </geometry> -->
      <geometry>
        <mesh filename="../meshes/fr_foot_link.STL" scale="1 1 1"/>
      </geometry>
    </collision>
    <inertial>
      <mass value="0.06"/>
      <inertia ixx="9.600000000000001e-04" ixy="0.0" ixz="0.0" iyy="9.600000000000001e-04" iyz="0.0" izz="9.600000000000001e-03"/>
    </inertial>
  </link>
  <!--        ************************** gazebo setting ***********************************************8-->
  <gazebo reference="RF_foot_fixed">
    <disableFixedJointLumping>true</disableFixedJointLumping>
  </gazebo>
  <gazebo reference="RF_hip">
    <!--            <mu1>0.5</mu1>-->
    <!--            <mu2>0.5</mu2>-->
    <!--            <self_collide>1</self_collide>-->
    <!--            <material>Gazebo/DarkGrey</material>-->
  </gazebo>
  <gazebo reference="RF_thigh">
    <mu1>0.6</mu1>
    <mu2>0.6</mu2>
    <self_collide>0</self_collide>
    <material>Gazebo/DarkGrey</material>
    <kp value="100000.0"/>
    <kd value="1.0"/>
  </gazebo>
  <gazebo reference="RF_calf">
    <mu1>0.6</mu1>
    <mu2>0.6</mu2>
    <self_collide>1</self_collide>
    <material>Gazebo/DarkGrey</material>
    <kp value="100000.0"/>
    <kd value="1.0"/>
    <maxVel>10.0</maxVel>
    <minDepth>0.001</minDepth>
  </gazebo>
  <transmission name="RF_hip_tran">
    <type>transmission_interface/SimpleTransmission</type>
    <joint name="RF_HAA">
      <hardwareInterface>hardware_interface/EffortJointInterface</hardwareInterface>
    </joint>
    <actuator name="RF_hip_motor">
      <hardwareInterface>hardware_interface/EffortJointInterface</hardwareInterface>
      <mechanicalReduction>1</mechanicalReduction>
    </actuator>
  </transmission>
  <transmission name="RF_thigh_tran">
    <type>transmission_interface/SimpleTransmission</type>
    <joint name="RF_HFE">
      <hardwareInterface>hardware_interface/EffortJointInterface</hardwareInterface>
    </joint>
    <actuator name="RF_thigh_motor">
      <hardwareInterface>hardware_interface/EffortJointInterface</hardwareInterface>
      <mechanicalReduction>1</mechanicalReduction>
    </actuator>
  </transmission>
  <transmission name="RF_calf_trans">
    <type>transmission_interface/SimpleTransmission</type>
    <joint name="RF_KFE">
      <hardwareInterface>hardware_interface/EffortJointInterface</hardwareInterface>
    </joint>
    <actuator name="RF_calf_motor">
      <hardwareInterface>hardware_interface/EffortJointInterface</hardwareInterface>
      <mechanicalReduction>1</mechanicalReduction>
    </actuator>
  </transmission>
  <!--       *********************************** abad description *************8-->
  <joint name="LF_HAA" type="revolute">
    <!--            insert start block from parent file-->
    <origin rpy="0 0 0" xyz="0.314 0.05 0"/>
    <parent link="trunk"/>
    <child link="LF_hip"/>
    <axis xyz="1 0 0"/>
    <dynamics damping="0" friction="0.01"/>
    <limit effort="45" lower="-0.8028514559173915" upper="0.8028514559173915" velocity="21"/>
  </joint>
  <link name="LF_hip">
    <visual>
      <origin rpy="0 0 0" xyz="0 0 0"/>
      <geometry>
        <mesh filename="../meshes/fl_abad_link.dae" scale="1 1 1"/>
      </geometry>
      <material name="orange"/>
    </visual>
    <collision>
      <origin rpy="1.5707963267948966 0 0" xyz="0.0 0.03 0"/>
      <geometry>
        <cylinder length="0.09" radius="0.055"/>
      </geometry>
    </collision>
    <!--            tochange here-->
    <!--            <collision>-->
    <!--                <origin rpy="${pi/2} 0 0"-->
    <!--                        xyz="${abad_origin_x*front_hind_mirror} ${abad_origin_y*left_right_mirror} 0"/>-->
    <!--                <geometry>-->
    <!--                    <xacro:if value="${(left_right_bool == True) and (front_hind_bool == True)}">-->
    <!--                        <mesh filename="../meshes/fl_abad_link.dae"-->
    <!--                              scale="1 1 1"/>-->
    <!--                    </xacro:if>-->
    <!--                    <xacro:if value="${(left_right_bool == False) and (front_hind_bool == True)}">-->
    <!--                        <mesh filename="../meshes/fr_abad_link.dae"-->
    <!--                              scale="1 1 1"/>-->
    <!--                    </xacro:if>-->
    <!--                    <xacro:if value="${(left_right_bool == True) and (front_hind_bool == False)}">-->
    <!--                        <mesh filename="../meshes/rl_abad_link.dae"-->
    <!--                              scale="1 1 1"/>-->
    <!--                    </xacro:if>-->
    <!--                    <xacro:if value="${(left_right_bool == False) and (front_hind_bool == False)}">-->
    <!--                        <mesh filename="../meshes/rr_abad_link.dae"-->
    <!--                              scale="1 1 1"/>-->
    <!--                    </xacro:if>-->
    <!--                </geometry>-->
    <!--            </collision>-->
    <inertial>
      <origin rpy="0 0 0" xyz="1.787e-05 0.00607236 -8.968e-05"/>
      <mass value="0.7766"/>
      <inertia ixx="0.00066364" ixy="0.0" ixz="0" iyy="0.00093712" iyz="2.89e-06" izz="0.00106375"/>
    </inertial>
  </link>
  <!--        *************************************** hip description ******************************************************-->
  <joint name="LF_HFE" type="revolute">
    <origin rpy="0 0 0" xyz="0 0.1408 0"/>
    <parent link="LF_hip"/>
    <child link="LF_thigh"/>
    <axis xyz="0 1 0"/>
    <dynamics damping="0" friction="0.01"/>
    <limit effort="45" lower="-4.1887902047863905" upper="4.1887902047863905" velocity="21"/>
  </joint>
  <link name="LF_thigh">
    <visual>
      <origin rpy="0 0 0" xyz="0 0 0"/>
      <geometry>
        <mesh filename="../meshes/fl_hip_link.dae" scale="1 1 1"/>
      </geometry>
      <material name="orange"/>
    </visual>
    <collision>
      <origin rpy="1.5707963267948966 0 0" xyz="0 0 0"/>
      <geometry>
        <cylinder length="0.039" radius="0.0375"/>
      </geometry>
    </collision>
    <collision>
      <origin rpy="1.5707963267948966 0 0" xyz="0 -0.04 0"/>
      <geometry>
        <cylinder length="0.048" radius="0.05"/>
      </geometry>
    </collision>
    <collision>
      <origin rpy="0 1.5707963267948966 0" xyz="0 0 -0.1382"/>
      <geometry>
        <box size="0.2159 0.05 0.05"/>
      </geometry>
    </collision>
    <inertial>
      <origin rpy="0 0 0" xyz="-0.00142243 -0.02451835 -0.06737031"/>
      <mass value="2.1028"/>
      <inertia ixx="0.03392455" ixy="-1.021e-05" ixz="-0.00038283" iyy="0.03116088" iyz="-4.69e-05" izz="0.00483256"/>
    </inertial>
  </link>
  <!--************************************************ knee description ***********************************************************8-->
  <joint name="LF_KFE" type="revolute">
    <origin rpy="0 0 0" xyz="0.0 0.0 -0.272"/>
    <parent link="LF_thigh"/>
    <child link="LF_calf"/>
    <axis xyz="0 1 0"/>
    <dynamics damping="0" friction="0.01"/>
    <limit effort="80" lower="-2.6965336943312392" upper="-0.9162978572970231" velocity="21"/>
  </joint>
  <link name="LF_calf">
    <visual>
      <origin rpy="0 0 0" xyz="0 0 0"/>
      <geometry>
        <mesh filename="../meshes/fl_knee_link.STL" scale="1 1 1"/>
      </geometry>
      <material name="orange"/>
    </visual>
    <collision>
      <origin rpy="0 0 0" xyz="0 0 0.0"/>
      <geometry>
        <mesh filename="../meshes/fl_knee_link.STL" scale="1 1 1"/>
      </geometry>
    </collision>
    <inertial>
      <origin rpy="0 0 0" xyz="-0.00804831 1.07e-06 -0.12689414"/>
      <mass value="0.4842"/>
      <inertia ixx="0.01527064" ixy="0.0" ixz="-0.00063844" iyy="0.01543121" iyz="2e-08" izz="0.00022068"/>
    </inertial>
  </link>
  <!--       ******************************* foot description ********************************8-->
  <joint name="LF_foot_fixed" type="fixed" dont_collapse="true">
    <origin rpy="0 0 0" xyz="0 0 -0.303542171457651"/>
    <!-- <origin rpy="0 0 0" xyz="0 0 0"/> -->
    <parent link="LF_calf"/>
    <child link="LF_FOOT"/>
  </joint>
  <link name="LF_FOOT">
    <visual>
      <origin rpy="0 0 0" xyz="0 0 0"/>
      <geometry>
        <mesh filename="../meshes/fl_foot_link.STL" scale="1 1 1"/>
      </geometry>
    </visual>
    <collision>
      <origin rpy="0 0 0" xyz="0 0 0"/>
      <!-- <geometry>
        <sphere radius="0.03"/>
      </geometry> -->
      <geometry>
        <mesh filename="../meshes/fl_foot_link.STL" scale="1 1 1"/>
      </geometry>
    </collision>
    <inertial>
      <mass value="0.06"/>
      <inertia ixx="9.600000000000001e-04" ixy="0.0" ixz="0.0" iyy="9.600000000000001e-04" iyz="0.0" izz="9.600000000000001e-03"/>
    </inertial>
  </link>
  <!--        ************************** gazebo setting ***********************************************8-->
  <gazebo reference="LF_foot_fixed">
    <disableFixedJointLumping>true</disableFixedJointLumping>
  </gazebo>
  <gazebo reference="LF_hip">
    <!--            <mu1>0.5</mu1>-->
    <!--            <mu2>0.5</mu2>-->
    <!--            <self_collide>1</self_collide>-->
    <!--            <material>Gazebo/DarkGrey</material>-->
  </gazebo>
  <gazebo reference="LF_thigh">
    <mu1>0.6</mu1>
    <mu2>0.6</mu2>
    <self_collide>0</self_collide>
    <material>Gazebo/DarkGrey</material>
    <kp value="100000.0"/>
    <kd value="1.0"/>
  </gazebo>
  <gazebo reference="LF_calf">
    <mu1>0.6</mu1>
    <mu2>0.6</mu2>
    <self_collide>1</self_collide>
    <material>Gazebo/DarkGrey</material>
    <kp value="100000.0"/>
    <kd value="1.0"/>
    <maxVel>10.0</maxVel>
    <minDepth>0.001</minDepth>
  </gazebo>
  <transmission name="LF_hip_tran">
    <type>transmission_interface/SimpleTransmission</type>
    <joint name="LF_HAA">
      <hardwareInterface>hardware_interface/EffortJointInterface</hardwareInterface>
    </joint>
    <actuator name="LF_hip_motor">
      <hardwareInterface>hardware_interface/EffortJointInterface</hardwareInterface>
      <mechanicalReduction>1</mechanicalReduction>
    </actuator>
  </transmission>
  <transmission name="LF_thigh_tran">
    <type>transmission_interface/SimpleTransmission</type>
    <joint name="LF_HFE">
      <hardwareInterface>hardware_interface/EffortJointInterface</hardwareInterface>
    </joint>
    <actuator name="LF_thigh_motor">
      <hardwareInterface>hardware_interface/EffortJointInterface</hardwareInterface>
      <mechanicalReduction>1</mechanicalReduction>
    </actuator>
  </transmission>
  <transmission name="LF_calf_trans">
    <type>transmission_interface/SimpleTransmission</type>
    <joint name="LF_KFE">
      <hardwareInterface>hardware_interface/EffortJointInterface</hardwareInterface>
    </joint>
    <actuator name="LF_calf_motor">
      <hardwareInterface>hardware_interface/EffortJointInterface</hardwareInterface>
      <mechanicalReduction>1</mechanicalReduction>
    </actuator>
  </transmission>
  <!--       *********************************** abad description *************8-->
  <joint name="RH_HAA" type="revolute">
    <!--            insert start block from parent file-->
    <origin rpy="0 0 0" xyz="-0.314 -0.05 0"/>
    <parent link="trunk"/>
    <child link="RH_hip"/>
    <axis xyz="1 0 0"/>
    <dynamics damping="0" friction="0.01"/>
    <limit effort="45" lower="-0.8028514559173915" upper="0.8028514559173915" velocity="21"/>
  </joint>
  <link name="RH_hip">
    <visual>
      <origin rpy="0 0 0" xyz="0 0 0"/>
      <geometry>
        <mesh filename="../meshes/rr_abad_link.dae" scale="1 1 1"/>
      </geometry>
      <material name="orange"/>
    </visual>
    <collision>
      <origin rpy="1.5707963267948966 0 0" xyz="-0.0 -0.03 0"/>
      <geometry>
        <cylinder length="0.09" radius="0.055"/>
      </geometry>
    </collision>
    <!--            tochange here-->
    <!--            <collision>-->
    <!--                <origin rpy="${pi/2} 0 0"-->
    <!--                        xyz="${abad_origin_x*front_hind_mirror} ${abad_origin_y*left_right_mirror} 0"/>-->
    <!--                <geometry>-->
    <!--                    <xacro:if value="${(left_right_bool == True) and (front_hind_bool == True)}">-->
    <!--                        <mesh filename="../meshes/fl_abad_link.dae"-->
    <!--                              scale="1 1 1"/>-->
    <!--                    </xacro:if>-->
    <!--                    <xacro:if value="${(left_right_bool == False) and (front_hind_bool == True)}">-->
    <!--                        <mesh filename="../meshes/fr_abad_link.dae"-->
    <!--                              scale="1 1 1"/>-->
    <!--                    </xacro:if>-->
    <!--                    <xacro:if value="${(left_right_bool == True) and (front_hind_bool == False)}">-->
    <!--                        <mesh filename="../meshes/rl_abad_link.dae"-->
    <!--                              scale="1 1 1"/>-->
    <!--                    </xacro:if>-->
    <!--                    <xacro:if value="${(left_right_bool == False) and (front_hind_bool == False)}">-->
    <!--                        <mesh filename="../meshes/rr_abad_link.dae"-->
    <!--                              scale="1 1 1"/>-->
    <!--                    </xacro:if>-->
    <!--                </geometry>-->
    <!--            </collision>-->
    <inertial>
      <origin rpy="0 0 0" xyz="-1.787e-05 -0.00607236 -8.968e-05"/>
      <mass value="0.7766"/>
      <inertia ixx="0.00066364" ixy="0.0" ixz="0" iyy="0.00093712" iyz="-2.89e-06" izz="0.00106375"/>
    </inertial>
  </link>
  <!--        *************************************** hip description ******************************************************-->
  <joint name="RH_HFE" type="revolute">
    <origin rpy="0 0 0" xyz="0 -0.1408 0"/>
    <parent link="RH_hip"/>
    <child link="RH_thigh"/>
    <axis xyz="0 1 0"/>
    <dynamics damping="0" friction="0.01"/>
    <limit effort="45" lower="-4.1887902047863905" upper="4.1887902047863905" velocity="21"/>
  </joint>
  <link name="RH_thigh">
    <visual>
      <origin rpy="0 0 0" xyz="0 0 0"/>
      <geometry>
        <mesh filename="../meshes/rr_hip_link.dae" scale="1 1 1"/>
      </geometry>
      <material name="orange"/>
    </visual>
    <collision>
      <origin rpy="1.5707963267948966 0 0" xyz="0 0 0"/>
      <geometry>
        <cylinder length="0.039" radius="0.0375"/>
      </geometry>
    </collision>
    <collision>
      <origin rpy="1.5707963267948966 0 0" xyz="0 0.04 0"/>
      <geometry>
        <cylinder length="0.048" radius="0.05"/>
      </geometry>
    </collision>
    <collision>
      <origin rpy="0 1.5707963267948966 0" xyz="0 0 -0.1382"/>
      <geometry>
        <box size="0.2159 0.05 0.05"/>
      </geometry>
    </collision>
    <inertial>
      <origin rpy="0 0 0" xyz="0.00142243 0.02451835 -0.06737031"/>
      <mass value="2.1028"/>
      <inertia ixx="0.03392455" ixy="1.021e-05" ixz="-0.00038283" iyy="0.03116088" iyz="4.69e-05" izz="0.00483256"/>
    </inertial>
  </link>
  <!--************************************************ knee description ***********************************************************8-->
  <joint name="RH_KFE" type="revolute">
    <origin rpy="0 0 0" xyz="-0.0 -0.0 -0.272"/>
    <parent link="RH_thigh"/>
    <child link="RH_calf"/>
    <axis xyz="0 1 0"/>
    <dynamics damping="0" friction="0.01"/>
    <limit effort="80" lower="0.9162978572970231" upper="2.6965336943312392" velocity="21"/>
  </joint>
  <link name="RH_calf">
    <visual>
      <origin rpy="0 0 0" xyz="0 0 0"/>
      <geometry>
        <mesh filename="../meshes/rr_knee_link.STL" scale="1 1 1"/>
      </geometry>
      <material name="orange"/>
    </visual>
    <collision>
      <origin rpy="0 0 0" xyz="0 0 0.0"/>
      <geometry>
        <mesh filename="../meshes/rr_knee_link.STL" scale="1 1 1"/>
      </geometry>
    </collision>
    <inertial>
      <origin rpy="0 0 0" xyz="-0.00804831 1.07e-06 -0.12689414"/>
      <mass value="0.4842"/>
      <inertia ixx="0.01527064" ixy="0.0" ixz="-0.00063844" iyy="0.01543121" iyz="2e-08" izz="0.00022068"/>
    </inertial>
  </link>
  <!--       ******************************* foot description ********************************8-->
  <joint name="RH_foot_fixed" type="fixed" dont_collapse="true">
    <origin rpy="0 0 0" xyz="0. 0 -0.303542171457651"/>
    <!-- <origin rpy="0 0 0" xyz="0 0 0"/> -->
    <parent link="RH_calf"/>
    <child link="RH_FOOT"/>
  </joint>
  <link name="RH_FOOT">
    <visual>
      <origin rpy="0 0 0" xyz="0 0 0"/>
      <geometry>
        <mesh filename="../meshes/rr_foot_link.STL" scale="1 1 1"/>
      </geometry>
    </visual>
    <collision>
      <origin rpy="0 0 0" xyz="0 0 0"/>
      <!-- <geometry>
        <sphere radius="0.03"/>
      </geometry> -->
      <geometry>
        <mesh filename="../meshes/rr_foot_link.STL" scale="1 1 1"/>
      </geometry>
    </collision>
    <inertial>
      <mass value="0.06"/>
      <inertia ixx="9.600000000000001e-04" ixy="0.0" ixz="0.0" iyy="9.600000000000001e-04" iyz="0.0" izz="9.600000000000001e-03"/>
    </inertial>
  </link>
  <!--        ************************** gazebo setting ***********************************************8-->
  <gazebo reference="RH_foot_fixed">
    <disableFixedJointLumping>true</disableFixedJointLumping>
  </gazebo>
  <gazebo reference="RH_hip">
    <!--            <mu1>0.5</mu1>-->
    <!--            <mu2>0.5</mu2>-->
    <!--            <self_collide>1</self_collide>-->
    <!--            <material>Gazebo/DarkGrey</material>-->
  </gazebo>
  <gazebo reference="RH_thigh">
    <mu1>0.6</mu1>
    <mu2>0.6</mu2>
    <self_collide>0</self_collide>
    <material>Gazebo/DarkGrey</material>
    <kp value="100000.0"/>
    <kd value="1.0"/>
  </gazebo>
  <gazebo reference="RH_calf">
    <mu1>0.6</mu1>
    <mu2>0.6</mu2>
    <self_collide>1</self_collide>
    <material>Gazebo/DarkGrey</material>
    <kp value="100000.0"/>
    <kd value="1.0"/>
    <maxVel>10.0</maxVel>
    <minDepth>0.001</minDepth>
  </gazebo>
  <transmission name="RH_hip_tran">
    <type>transmission_interface/SimpleTransmission</type>
    <joint name="RH_HAA">
      <hardwareInterface>hardware_interface/EffortJointInterface</hardwareInterface>
    </joint>
    <actuator name="RH_hip_motor">
      <hardwareInterface>hardware_interface/EffortJointInterface</hardwareInterface>
      <mechanicalReduction>1</mechanicalReduction>
    </actuator>
  </transmission>
  <transmission name="RH_thigh_tran">
    <type>transmission_interface/SimpleTransmission</type>
    <joint name="RH_HFE">
      <hardwareInterface>hardware_interface/EffortJointInterface</hardwareInterface>
    </joint>
    <actuator name="RH_thigh_motor">
      <hardwareInterface>hardware_interface/EffortJointInterface</hardwareInterface>
      <mechanicalReduction>1</mechanicalReduction>
    </actuator>
  </transmission>
  <transmission name="RH_calf_trans">
    <type>transmission_interface/SimpleTransmission</type>
    <joint name="RH_KFE">
      <hardwareInterface>hardware_interface/EffortJointInterface</hardwareInterface>
    </joint>
    <actuator name="RH_calf_motor">
      <hardwareInterface>hardware_interface/EffortJointInterface</hardwareInterface>
      <mechanicalReduction>1</mechanicalReduction>
    </actuator>
  </transmission>
  <!--       *********************************** abad description *************8-->
  <joint name="LH_HAA" type="revolute">
    <!--            insert start block from parent file-->
    <origin rpy="0 0 0" xyz="-0.314 0.05 0"/>
    <parent link="trunk"/>
    <child link="LH_hip"/>
    <axis xyz="1 0 0"/>
    <dynamics damping="0" friction="0.01"/>
    <limit effort="45" lower="-0.8028514559173915" upper="0.8028514559173915" velocity="21"/>
  </joint>
  <link name="LH_hip">
    <visual>
      <origin rpy="0 0 0" xyz="0 0 0"/>
      <geometry>
        <mesh filename="../meshes/rl_abad_link.dae" scale="1 1 1"/>
      </geometry>
      <material name="orange"/>
    </visual>
    <collision>
      <origin rpy="1.5707963267948966 0 0" xyz="-0.0 0.03 0"/>
      <geometry>
        <cylinder length="0.09" radius="0.055"/>
      </geometry>
    </collision>
    <!--            tochange here-->
    <!--            <collision>-->
    <!--                <origin rpy="${pi/2} 0 0"-->
    <!--                        xyz="${abad_origin_x*front_hind_mirror} ${abad_origin_y*left_right_mirror} 0"/>-->
    <!--                <geometry>-->
    <!--                    <xacro:if value="${(left_right_bool == True) and (front_hind_bool == True)}">-->
    <!--                        <mesh filename="../meshes/fl_abad_link.dae"-->
    <!--                              scale="1 1 1"/>-->
    <!--                    </xacro:if>-->
    <!--                    <xacro:if value="${(left_right_bool == False) and (front_hind_bool == True)}">-->
    <!--                        <mesh filename="../meshes/fr_abad_link.dae"-->
    <!--                              scale="1 1 1"/>-->
    <!--                    </xacro:if>-->
    <!--                    <xacro:if value="${(left_right_bool == True) and (front_hind_bool == False)}">-->
    <!--                        <mesh filename="../meshes/rl_abad_link.dae"-->
    <!--                              scale="1 1 1"/>-->
    <!--                    </xacro:if>-->
    <!--                    <xacro:if value="${(left_right_bool == False) and (front_hind_bool == False)}">-->
    <!--                        <mesh filename="../meshes/rr_abad_link.dae"-->
    <!--                              scale="1 1 1"/>-->
    <!--                    </xacro:if>-->
    <!--                </geometry>-->
    <!--            </collision>-->
    <inertial>
      <origin rpy="0 0 0" xyz="-1.787e-05 0.00607236 -8.968e-05"/>
      <mass value="0.7766"/>
      <inertia ixx="0.00066364" ixy="-0.0" ixz="0" iyy="0.00093712" iyz="2.89e-06" izz="0.00106375"/>
    </inertial>
  </link>
  <!--        *************************************** hip description ******************************************************-->
  <joint name="LH_HFE" type="revolute">
    <origin rpy="0 0 0" xyz="0 0.1408 0"/>
    <parent link="LH_hip"/>
    <child link="LH_thigh"/>
    <axis xyz="0 1 0"/>
    <dynamics damping="0" friction="0.01"/>
    <limit effort="45" lower="-4.1887902047863905" upper="4.1887902047863905" velocity="21"/>
  </joint>
  <link name="LH_thigh">
    <visual>
      <origin rpy="0 0 0" xyz="0 0 0"/>
      <geometry>
        <mesh filename="../meshes/rl_hip_link.dae" scale="1 1 1"/>
      </geometry>
      <material name="orange"/>
    </visual>
    <collision>
      <origin rpy="1.5707963267948966 0 0" xyz="0 0 0"/>
      <geometry>
        <cylinder length="0.039" radius="0.0375"/>
      </geometry>
    </collision>
    <collision>
      <origin rpy="1.5707963267948966 0 0" xyz="0 -0.04 0"/>
      <geometry>
        <cylinder length="0.048" radius="0.05"/>
      </geometry>
    </collision>
    <collision>
      <origin rpy="0 1.5707963267948966 0" xyz="0 0 -0.1382"/>
      <geometry>
        <box size="0.2159 0.05 0.05"/>
      </geometry>
    </collision>
    <inertial>
      <origin rpy="0 0 0" xyz="0.00142243 -0.02451835 -0.06737031"/>
      <mass value="2.1028"/>
      <inertia ixx="0.03392455" ixy="-1.021e-05" ixz="-0.00038283" iyy="0.03116088" iyz="-4.69e-05" izz="0.00483256"/>
    </inertial>
  </link>
  <!--************************************************ knee description ***********************************************************8-->
  <joint name="LH_KFE" type="revolute">
    <origin rpy="0 0 0" xyz="-0.0 0.0 -0.272"/>
    <parent link="LH_thigh"/>
    <child link="LH_calf"/>
    <axis xyz="0 1 0"/>
    <dynamics damping="0" friction="0.01"/>
    <limit effort="80" lower="0.9162978572970231" upper="2.6965336943312392" velocity="21"/>
  </joint>
  <link name="LH_calf">
    <visual>
      <origin rpy="0 0 0" xyz="0 0 0"/>
      <geometry>
        <mesh filename="../meshes/rl_knee_link.STL" scale="1 1 1"/>
      </geometry>
      <material name="orange"/>
    </visual>
    <collision>
      <origin rpy="0 0 0" xyz="0 0 0.0"/>
      <geometry>
        <mesh filename="../meshes/rl_knee_link.STL" scale="1 1 1"/>
      </geometry>
    </collision>
    <inertial>
      <origin rpy="0 0 0" xyz="-0.00804831 1.07e-06 -0.12689414"/>
      <mass value="0.4842"/>
      <inertia ixx="0.01527064" ixy="0.0" ixz="-0.00063844" iyy="0.01543121" iyz="2e-08" izz="0.00022068"/>
    </inertial>
  </link>
  <!--       ******************************* foot description ********************************8-->
  <joint name="LH_foot_fixed" type="fixed" dont_collapse="true">
    <origin rpy="0 0 0" xyz="0 0 -0.303542171457651"/>
    <!-- <origin rpy="0 0 0" xyz="0 0 0"/> -->
    <parent link="LH_calf"/>
    <child link="LH_FOOT"/>
  </joint>
  <link name="LH_FOOT">
    <visual>
      <origin rpy="0 0 0" xyz="0 0 0"/>
      <geometry>
        <mesh filename="../meshes/rl_foot_link.STL" scale="1 1 1"/>
      </geometry>
    </visual>
    <collision>
      <origin rpy="0 0 0" xyz="0 0 0"/>
      <!-- <geometry>
        <sphere radius="0.03"/>
      </geometry> -->
      <geometry>
        <mesh filename="../meshes/rl_foot_link.STL" scale="1 1 1"/>
      </geometry>
    </collision>
    <inertial>
      <mass value="0.06"/>
      <inertia ixx="9.600000000000001e-04" ixy="0.0" ixz="0.0" iyy="9.600000000000001e-04" iyz="0.0" izz="9.600000000000001e-03"/>
    </inertial>
  </link>
  <!--        ************************** gazebo setting ***********************************************8-->
  <gazebo reference="LH_foot_fixed">
    <disableFixedJointLumping>true</disableFixedJointLumping>
  </gazebo>
  <gazebo reference="LH_hip">
    <!--            <mu1>0.5</mu1>-->
    <!--            <mu2>0.5</mu2>-->
    <!--            <self_collide>1</self_collide>-->
    <!--            <material>Gazebo/DarkGrey</material>-->
  </gazebo>
  <gazebo reference="LH_thigh">
    <mu1>0.6</mu1>
    <mu2>0.6</mu2>
    <self_collide>0</self_collide>
    <material>Gazebo/DarkGrey</material>
    <kp value="100000.0"/>
    <kd value="1.0"/>
  </gazebo>
  <gazebo reference="LH_calf">
    <mu1>0.6</mu1>
    <mu2>0.6</mu2>
    <self_collide>1</self_collide>
    <material>Gazebo/DarkGrey</material>
    <kp value="100000.0"/>
    <kd value="1.0"/>
    <maxVel>10.0</maxVel>
    <minDepth>0.001</minDepth>
  </gazebo>
  <transmission name="LH_hip_tran">
    <type>transmission_interface/SimpleTransmission</type>
    <joint name="LH_HAA">
      <hardwareInterface>hardware_interface/EffortJointInterface</hardwareInterface>
    </joint>
    <actuator name="LH_hip_motor">
      <hardwareInterface>hardware_interface/EffortJointInterface</hardwareInterface>
      <mechanicalReduction>1</mechanicalReduction>
    </actuator>
  </transmission>
  <transmission name="LH_thigh_tran">
    <type>transmission_interface/SimpleTransmission</type>
    <joint name="LH_HFE">
      <hardwareInterface>hardware_interface/EffortJointInterface</hardwareInterface>
    </joint>
    <actuator name="LH_thigh_motor">
      <hardwareInterface>hardware_interface/EffortJointInterface</hardwareInterface>
      <mechanicalReduction>1</mechanicalReduction>
    </actuator>
  </transmission>
  <transmission name="LH_calf_trans">
    <type>transmission_interface/SimpleTransmission</type>
    <joint name="LH_KFE">
      <hardwareInterface>hardware_interface/EffortJointInterface</hardwareInterface>
    </joint>
    <actuator name="LH_calf_motor">
      <hardwareInterface>hardware_interface/EffortJointInterface</hardwareInterface>
      <mechanicalReduction>1</mechanicalReduction>
    </actuator>
  </transmission>
</robot>

